<?xml version="1.0" ?>
<!-- =================================================================================== -->
<!-- |    This document was autogenerated by xacro from diff.xacro                     | -->
<!-- |    EDITING THIS FILE BY HAND IS NOT RECOMMENDED                                 | -->
<!-- =================================================================================== -->
<robot name="diff">
  <!-- 定义方形底盘 -->
  <link name="base_link">
    <visual>
      <geometry>
        <box size="0.5 0.3 0.1"/>
      </geometry>
      <material name="base_link_material">
        <color rgba="0.0 0.0 1.0 1.0"/>
        <!-- 蓝色车体 -->
      </material>
    </visual>
    <collision>
      <geometry>
        <box size="0.5 0.3 0.1"/>
      </geometry>
    </collision>
    <inertial>
      <mass value="1.0"/>
      <inertia ixx="0.01" ixy="0.0" ixz="0.0" iyy="0.01" iyz="0.0" izz="0.01"/>
    </inertial>
  </link>
  <link name="left_wheel_link">
    <visual>
      <geometry>
        <cylinder length="0.05" radius="0.3"/>
      </geometry>
      <material name="left_wheel_link_material">
        <color rgba="1.0 0.0 0.0 1.0"/>
        <!-- 红色轮子 -->
      </material>
    </visual>
    <collision>
      <geometry>
        <cylinder length="0.05" radius="0.3"/>
      </geometry>
    </collision>
    <inertial>
      <mass value="0.1"/>
      <inertia ixx="0.001" ixy="0.0" ixz="0.0" iyy="0.001" iyz="0.0" izz="0.001"/>
    </inertial>
  </link>
  <joint name="left_wheel_link_joint" type="continuous">
    <parent link="base_link"/>
    <child link="left_wheel_link"/>
    <origin rpy="1.5708 0 0" xyz="0.0 0.15 0"/>
    <axis xyz="0 0 1"/>
  </joint>
  <link name="right_wheel_link">
    <visual>
      <geometry>
        <cylinder length="0.05" radius="0.3"/>
      </geometry>
      <material name="right_wheel_link_material">
        <color rgba="1.0 0.0 0.0 1.0"/>
        <!-- 红色轮子 -->
      </material>
    </visual>
    <collision>
      <geometry>
        <cylinder length="0.05" radius="0.3"/>
      </geometry>
    </collision>
    <inertial>
      <mass value="0.1"/>
      <inertia ixx="0.001" ixy="0.0" ixz="0.0" iyy="0.001" iyz="0.0" izz="0.001"/>
    </inertial>
  </link>
  <joint name="right_wheel_link_joint" type="continuous">
    <parent link="base_link"/>
    <child link="right_wheel_link"/>
    <origin rpy="1.5708 0 0" xyz="0.0 -0.15 0"/>
    <axis xyz="0 0 1"/>
  </joint>
</robot>
