<?xml version="1.0" encoding="utf-8"?>
<robot name="diff"> 
  <!-- 定义方形底盘 -->  
  <link name="base_link"> 
    <visual> 
      <geometry> 
        <box size="0.5 0.3 0.1"/> 
      </geometry>  
      <material name="base_link_material"> 
        <color rgba="0.0 0.0 1.0 1.0"/> <!-- 蓝色车体 -->
      </material> 
    </visual>  
    <collision> 
      <geometry> 
        <box size="0.5 0.3 0.1"/> 
      </geometry> 
    </collision>  
    <inertial> 
      <mass value="1.0"/>  
      <inertia ixx="0.01" ixy="0.0" ixz="0.0" iyy="0.01" iyz="0.0" izz="0.01"/> 
    </inertial> 
  </link>  
  <!-- 定义左驱动轮 -->  
  <link name="left_wheel_link"> 
    <visual> 
      <geometry> 
        <!-- 减小轮子宽度 -->
        <cylinder radius="0.05" length="0.05"/> 
      </geometry>  
      <material name="left_wheel_material"> 
        <color rgba="1.0 0.0 0.0 1.0"/> <!-- 红色轮子 -->
      </material> 
    </visual>  
    <collision> 
      <geometry> 
        <cylinder radius="0.05" length="0.05"/> 
      </geometry> 
    </collision>  
    <inertial> 
      <mass value="0.1"/>  
      <inertia ixx="0.001" ixy="0.0" ixz="0.0" iyy="0.001" iyz="0.0" izz="0.001"/> 
    </inertial> 
  </link>  
  <!-- 定义右驱动轮 -->  
  <link name="right_wheel_link"> 
    <visual> 
      <geometry> 
        <!-- 减小轮子宽度 -->
        <cylinder radius="0.05" length="0.05"/> 
      </geometry>  
      <material name="right_wheel_material"> 
        <color rgba="1.0 0.0 0.0 1.0"/> <!-- 红色轮子 -->
      </material> 
    </visual>  
    <collision> 
      <geometry> 
        <cylinder radius="0.05" length="0.05"/> 
      </geometry> 
    </collision>  
    <inertial> 
      <mass value="0.1"/>  
      <inertia ixx="0.001" ixy="0.0" ixz="0.0" iyy="0.001" iyz="0.0" izz="0.001"/> 
    </inertial> 
  </link>  
  <!-- 定义左驱动轮关节 -->  
  <joint name="left_wheel_joint" type="continuous"> 
    <parent link="base_link"/>  
    <child link="left_wheel_link"/>  
    <!-- 调整轮子位置到车体中心线 -->
    <origin xyz="0.0 0.15 0" rpy="1.5708 0 0"/>  
    <axis xyz="0 0 1"/> 
  </joint>  
  <!-- 定义右驱动轮关节 -->  
  <joint name="right_wheel_joint" type="continuous"> 
    <parent link="base_link"/>  
    <child link="right_wheel_link"/>  
    <!-- 调整轮子位置到车体中心线 -->
    <origin xyz="0.0 -0.15 0" rpy="1.5708 0 0"/>  
    <axis xyz="0 0 1"/> 
  </joint> 
</robot>